Workbook

Sheet Daily Profit Calculator - 02
B1: Total Production | C1: Vehicle | I1: Shop | T1: Daily Production related expenses
C2: Stocked | D2: Remaining | E2: Cost | F2: Income | G2: Profit | I2: Soled | J2: Stock + Vehicle | K2: Remaining | L2: Cost | M2: Income | N2: Income 02 | O2: Profit | P2: Remaining | Q2: Cost | T2: Santha's Salary | U2: 0
A3: Bread | B3: 80 | C3: 34 | D3: 0 | E3: =((C3-D3) * 'Product Cost & Prices'!B2) -> 2567.2429 | F3: =((C3-D3) * 'Product Cost & Prices'!F2) -> 4420 | G3: =((C3-D3) * 'Product Cost & Prices'!F2) - ((C3-D3) * 'Product Cost & Prices'!B2) -> 1852.7571 | I3: 25 | J3: =I3 -> 25 | K3: 0 | L3: =(J3-K3) * 'Product Cost & Prices'!B2 -> 1887.6786 | M3: =($J3-$K3) * 'Product Cost & Prices'!E2 -> 2750 | N3: =($J3-$K3) * 'Product Cost & Prices'!E2 -> 2750 | O3: =((J3-K3) * 'Product Cost & Prices'!E2) - ((J3-K3) * 'Product Cost & Prices'!B2) -> 862.32143 | Q3: =P3*'Bread Cost Calculator'!E9 -> 0 | T3: Driver's Salary | U3: 0
A4: Sandwitch Bread | B4: 2 | C4: 0 | D4: 0 | E4: =((C4-D4) * 'Product Cost & Prices'!B3) -> 0 | F4: =((C4-D4) * 'Product Cost & Prices'!F3) -> 0 | I4: 0 | J4: =I4 -> 0 | K4: 0 | L4: =(J4-K4) * 'Product Cost & Prices'!B3 -> 0 | M4: =($J4-$K4) * 'Product Cost & Prices'!E3 -> 0 | N4: =($J4-$K4) * 'Product Cost & Prices'!E3 -> 0 | O4: =((J4-K4) * 'Product Cost & Prices'!E3) - ((J4-K4) * 'Product Cost & Prices'!B3) -> 0 | Q4: =P4*'Bread Cost Calculator'!E9 -> 0 | T4: shop's salary | U4: 0
A5: Fish Bun | B5: 55 | C5: 35 | D5: 6 | E5: =((C5-D5) * 'Product Cost & Prices'!B5) -> 557.34781 | F5: =((C5-D5) * 'Product Cost & Prices'!F5) -> 1740 | G5: =((C5-D5) * 'Product Cost & Prices'!F5) - ((C5-D5) * 'Product Cost & Prices'!B5) -> 1182.6522 | I5: 25 | J5: =I5 -> 25 | K5: 0 | L5: =(J5-K5) * 'Product Cost & Prices'!B5 -> 480.47225 | M5: =(J5-K5) * 'Product Cost & Prices'!E5 -> 1375 | N5: =(J5-K5) * 'Product Cost & Prices'!E5 -> 1375 | O5: =((J5-K5) * 'Product Cost & Prices'!E5) - ((J5-K5) * 'Product Cost & Prices'!B5) -> 894.52775 | Q5: =P5*'Genaral Bun Cost Calculator'!D32 -> 0 | T5: Accounts Salary | U5: 0
A6: Wiyan Roll | B6: 15 | C6: 10 | D6: 0 | E6: =((C6-D6) * 'Product Cost & Prices'!B6) -> 164.41149 | F6: =((C6-D6) * 'Product Cost & Prices'!F6) -> 400 | G6: =((C6-D6) * 'Product Cost & Prices'!F6) - ((C6-D6) * 'Product Cost & Prices'!B6) -> 235.58851 | I6: 5 | J6: =I6 -> 5 | K6: 0 | L6: =(J6-K6) * 'Product Cost & Prices'!B6 -> 82.205745 | M6: =(J6-K6) * 'Product Cost & Prices'!E6 -> 175 | N6: =(J6-K6) * 'Product Cost & Prices'!E6 -> 175 | O6: =((J6-K6) * 'Product Cost & Prices'!E6) - ((J6-K6) * 'Product Cost & Prices'!B6) -> 92.794255 | Q6: =P6*'Genaral Bun Cost Calculator'!D14 -> 0 | T6: Vehicle Fuel & Maintainance | U6: 0
A7: Jam Bun | B7: 50 | C7: 40 | D7: 9 | E7: =((C7-D7) * 'Product Cost & Prices'!B7) -> 620.57525 | F7: =((C7-D7) * 'Product Cost & Prices'!F7) -> 1550 | G7: =((C7-D7) * 'Product Cost & Prices'!F7) - ((C7-D7) * 'Product Cost & Prices'!B7) -> 929.42475 | I7: 29 | J7: =I7 -> 29 | K7: 0 | L7: =(J7-K7) * 'Product Cost & Prices'!B7 -> 580.53814 | M7: =(J7-K7) * 'Product Cost & Prices'!E7 -> 1305 | N7: =(J7-K7) * 'Product Cost & Prices'!E7 -> 1305 | O7: =((J7-K7) * 'Product Cost & Prices'!E7) - ((J7-K7) * 'Product Cost & Prices'!B7) -> 724.46186 | Q7: =P7*'Genaral Bun Cost Calculator'!D21 -> 0 | T7: Timber | U7: 0
A8: Roast Bread | B8: 60 | C8: 60 | D8: 0 | E8: =((C8-D8) * 'Product Cost & Prices'!B14) -> 744.77528 | F8: =((C8-D8) * 'Product Cost & Prices'!F14) -> 2100 | G8: =((C8-D8) * 'Product Cost & Prices'!F14) - ((C8-D8) * 'Product Cost & Prices'!B14) -> 1355.2247 | I8: 6 | J8: =I8 -> 6 | K8: 0 | L8: =(J8-K8) * 'Product Cost & Prices'!B14 -> 74.477528 | M8: =(J8-K8) * 'Product Cost & Prices'!E14 -> 180 | N8: =(J8-K8) * 'Product Cost & Prices'!E14 -> 180 | O8: =((J8-K8) * 'Product Cost & Prices'!E14) - ((J8-K8) * 'Product Cost & Prices'!B14) -> 105.52247 | Q8: =P8*'Roast Bread Cost Calculator'!E9 -> 0 | T8: Father's Allocation | U8: 0
A9: Pizza | B9: 10 | C9: 10 | D9: 4 | E9: =((C9-D9) * 'Product Cost & Prices'!B8) -> 274.55835 | F9: =((C9-D9) * 'Product Cost & Prices'!F8) -> 600 | G9: =((C9-D9) * 'Product Cost & Prices'!F8) - ((C9-D9) * 'Product Cost & Prices'!B8) -> 325.44165 | I9: 0 | J9: 0 | K9: 0 | L9: =(J9-K9) * 'Product Cost & Prices'!B8 -> 0 | M9: =(J9-K9) * 'Product Cost & Prices'!E8 -> 0 | N9: =(J9-K9) * 'Product Cost & Prices'!E8 -> 0 | O9: =((J9-K9) * 'Product Cost & Prices'!E8) - ((J9-K9) * 'Product Cost & Prices'!B8) -> 0 | T9: Mother's Allocation | U9: 0
A10: Sausages Bun | C10: 0 | D10: 0 | E10: =((C10-D10) * 'Product Cost & Prices'!B9) -> 0 | F10: =((C10-D10) * 'Product Cost & Prices'!F9) -> 0 | G10: =((C10-D10) * 'Product Cost & Prices'!F9) - ((C10-D10) * 'Product Cost & Prices'!B9) -> 0 | I10: 0 | J10: =I10 -> 0 | K10: 0 | L10: =(J10-K10) * 'Product Cost & Prices'!B9 -> 0 | M10: =(J10-K10) * 'Product Cost & Prices'!E9 -> 0 | N10: 0 | O10: =((J10-K10) * 'Product Cost & Prices'!E9) - ((J10-K10) * 'Product Cost & Prices'!B9) -> 0 | T10: Salary Advance | U10: 0
A11: T-Bun | C11: 12 | D11: 11 | E11: =((C11-D11) * 'Product Cost & Prices'!B10) -> 31.702174 | F11: =((C11-D11) * 'Product Cost & Prices'!F10) -> 50 | G11: =((C11-D11) * 'Product Cost & Prices'!F10) - ((C11-D11) * 'Product Cost & Prices'!B10) -> 18.297826 | I11: 4 | J11: =I11 -> 4 | K11: 0 | L11: =(J11-K11) * 'Product Cost & Prices'!B10 -> 126.8087 | M11: =(J11-K11) * 'Product Cost & Prices'!E10 -> 180 | N11: =(J11-K11) * 'Product Cost & Prices'!E10 -> 180 | O11: =((J11-K11) * 'Product Cost & Prices'!E10) - ((J11-K11) * 'Product Cost & Prices'!B10) -> 53.191304 | T11: Not received | U11: 0
A12: Cream Bun (2 Pieces) | C12: 10 | D12: 6 | E12: =((C12-D12) * 'Product Cost & Prices'!B11) -> 144.73605 | F12: =((C12-D12) * 'Product Cost & Prices'!F11) -> 240 | G12: =((C12-D12) * 'Product Cost & Prices'!F11) - ((C12-D12) * 'Product Cost & Prices'!B11) -> 95.263949 | I12: 8 | J12: =I12 -> 8 | K12: 0 | L12: =(J12-K12) * 'Product Cost & Prices'!B11 -> 289.4721 | M12: =(J12-K12) * 'Product Cost & Prices'!E11 -> 440 | N12: =(J12-K12) * 'Product Cost & Prices'!E11 -> 440 | O12: =((J12-K12) * 'Product Cost & Prices'!E11) - ((J12-K12) * 'Product Cost & Prices'!B11) -> 150.5279 | T12: Total | U12: 0
A13: Wandu | B13: 20 | C13: 20 | D13: 13 | E13: =((C13-D13) * 'Product Cost & Prices'!B12) -> 166.502 | F13: =((C13-D13) * 'Product Cost & Prices'!F12) -> 350 | G13: =((C13-D13) * 'Product Cost & Prices'!F12) - ((C13-D13) * 'Product Cost & Prices'!B12) -> 183.498 | I13: 6 | J13: =I13 -> 6 | K13: 0 | L13: =(J13-K13) * 'Product Cost & Prices'!B12 -> 142.716 | M13: =(J13-K13) * 'Product Cost & Prices'!E12 -> 270 | N13: =(J13-K13) * 'Product Cost & Prices'!E12 -> 270 | O13: =((J13-K13) * 'Product Cost & Prices'!E12) - ((J13-K13) * 'Product Cost & Prices'!B12) -> 127.284
A14: Cup Cake | C14: 0 | D14: 0 | E14: =((C14-D14) * 'Product Cost & Prices'!B15) -> 0 | F14: =((C14-D14) * 'Product Cost & Prices'!F15) -> 0 | I14: 0 | J14: =I14 -> 0 | K14: 0 | L14: =(J14-K14) * 'Product Cost & Prices'!B15 -> 0 | M14: =(J14-K14) * 'Product Cost & Prices'!E13 -> 0 | N14: =(J14-K14) * 'Product Cost & Prices'!E15 -> 0 | O14: =((J14-K14) * 'Product Cost & Prices'!E15) - ((J14-K14) * 'Product Cost & Prices'!B15) -> 0
A15: Wafers Cake | C15: 0 | D15: 0 | E15: =((C15-D15) * 'Product Cost & Prices'!B13) -> 0 | F15: =((C15-D15) * 'Product Cost & Prices'!F13) -> 0 | G15: =((C15-D15) * 'Product Cost & Prices'!F13) - ((C15-D15) * 'Product Cost & Prices'!B13) -> 0 | I15: 0 | J15: =I15 -> 0 | K15: 0 | L15: =(J15-K15) * 'Product Cost & Prices'!B13 -> 0 | M15: =(J15-K15) * 'Product Cost & Prices'!E13 -> 0 | N15: =(J15-K15) * 'Product Cost & Prices'!E13 -> 0 | O15: =((J15-K15) * 'Product Cost & Prices'!E13) - ((J15-K15) * 'Product Cost & Prices'!B13) -> 0
A16: pieces packet | C16: 0 | I16: 0 | N16: 0
A17: Butter Buscuit | C17: 0 | I17: 0
A18: Burger Bun | C18: 0 | D18: 0 | E18: =((C18-D18) * 'Product Cost & Prices'!B16) -> 0 | F18: =((C18-D18) * 'Product Cost & Prices'!F16) -> 0
A19: Bread (For Resale) | C19: 28 | E19: =((C19-D19) * 'Product Cost & Prices'!B4) -> 2114.2 | F19: =((C19-D19) * 'Product Cost & Prices'!F4) -> 3080 | G19: =((C19-D19) * 'Product Cost & Prices'!F4) - ((C19-D19) * 'Product Cost & Prices'!B4) -> 965.8
A20: Total Profit | E20: =SUM(E3:E19) -> 7386.0513 | F20: =SUM(F3:F19) -> 14530 | G20: =SUM(G3:G19) -> 7143.9487 | I20: Total Profit | L20: =SUM(L3:L15) -> 3664.369 | M20: =SUM(M3:M15) -> 6675 | N20: =SUM(N3:N16) -> 6675 | O20: =SUM(O3:O15) -> 3010.631 | Q20: =sum(Q3:Q17) -> 0
A21: Gross Profit | F21: =sum(F20-E20) -> 7143.9487 | I21: Gross Profit | O21: =SUM(N20-L20) -> 3010.631
C24: =CONCAT("Income for ", TEXT(Today(), "MMMM d, yyyy")) -> Income for January 11, 2026 | K24: =SUM(F20+N20) -> 21205
C25: =CONCAT("Cost for ", TEXT(Today(), "MMMM d, yyyy")) -> Cost for January 11, 2026 | K25: =SUM(E20+L20) + U12 -> 11050.42
C26: =CONCAT("Gross Profit for ", TEXT(Today(), "MMMM d, yyyy")) -> Gross Profit for January 11, 2026 | K26: =SUM(F21+O21) -> 10154.58
C27: =CONCAT("Net Profit for ", TEXT(Today(), "MMMM d, yyyy")) -> Net Profit for January 11, 2026 | K27: =SUM(K24-K25) -> 10154.58
C39: Amount | D39: Note Count | E39: Total | P39: `
C40: 20 | D40: 4 | E40: =C40*D40 -> 80
C41: 50 | D41: 17 | E41: =C41*D41 -> 850
C42: 100 | D42: 21 | E42: =C42*D42 -> 2100
C43: 500 | D43: 0 | E43: =C43*D43 -> 0
C44: 1000 | D44: 0 | E44: =C44*D44 -> 0
C45: 5000 | D45: 0 | E45: =C45*D45 -> 0
E46: =SUM(E40:E45) -> 3030

Sheet Daily Profit Calculator - 01
B1: Total Production | C1: Vehicle | I1: Shop | T1: Daily Production related expenses
C2: Stocked | D2: Remaining | E2: Cost | F2: Income | G2: Profit | I2: Soled | J2: Stock + Vehicle | K2: Remaining | L2: Cost | M2: Income | N2: Income 02 | O2: Profit | P2: Remaining | Q2: Cost | T2: Santha's Salary | U2: 2000
A3: Bread | B3: 80 | C3: 36 | D3: 0 | E3: =((C3-D3) * 'Product Cost & Prices'!B2) -> 2718.2571 | F3: =((C3-D3) * 'Product Cost & Prices'!F2) -> 4680 | G3: =((C3-D3) * 'Product Cost & Prices'!F2) - ((C3-D3) * 'Product Cost & Prices'!B2) -> 1961.7429 | I3: 15 | J3: =I3 -> 15 | K3: 0 | L3: =(J3-K3) * 'Product Cost & Prices'!B2 -> 1132.6071 | M3: =($J3-$K3) * 'Product Cost & Prices'!E2 -> 1650 | N3: =($J3-$K3) * 'Product Cost & Prices'!E2 -> 1650 | O3: =((J3-K3) * 'Product Cost & Prices'!E2) - ((J3-K3) * 'Product Cost & Prices'!B2) -> 517.39286 | Q3: =P3*'Bread Cost Calculator'!E9 -> 0 | T3: Driver's Salary | U3: 2000
A4: Sandwitch Bread | B4: 2 | C4: 0 | D4: 0 | E4: =((C4-D4) * 'Product Cost & Prices'!B3) -> 0 | F4: =((C4-D4) * 'Product Cost & Prices'!F3) -> 0 | I4: 0 | J4: =I4 -> 0 | K4: 0 | L4: =(J4-K4) * 'Product Cost & Prices'!B3 -> 0 | M4: =($J4-$K4) * 'Product Cost & Prices'!E3 -> 0 | N4: =($J4-$K4) * 'Product Cost & Prices'!E3 -> 0 | O4: =((J4-K4) * 'Product Cost & Prices'!E3) - ((J4-K4) * 'Product Cost & Prices'!B3) -> 0 | Q4: =P4*'Bread Cost Calculator'!E9 -> 0 | T4: shop's salary | U4: 0
A5: Fish Bun | B5: 55 | C5: 40 | D5: 0 | E5: =((C5-D5) * 'Product Cost & Prices'!B5) -> 768.7556 | F5: =((C5-D5) * 'Product Cost & Prices'!F5) -> 2400 | G5: =((C5-D5) * 'Product Cost & Prices'!F5) - ((C5-D5) * 'Product Cost & Prices'!B5) -> 1631.2444 | I5: 7 | J5: =I5 -> 7 | K5: 0 | L5: =(J5-K5) * 'Product Cost & Prices'!B5 -> 134.53223 | M5: =(J5-K5) * 'Product Cost & Prices'!E5 -> 385 | N5: =(J5-K5) * 'Product Cost & Prices'!E5 -> 385 | O5: =((J5-K5) * 'Product Cost & Prices'!E5) - ((J5-K5) * 'Product Cost & Prices'!B5) -> 250.46777 | Q5: =P5*'Genaral Bun Cost Calculator'!D32 -> 0 | T5: Accounts Salary | U5: 0
A6: Wiyan Roll | B6: 15 | C6: 10 | D6: 0 | E6: =((C6-D6) * 'Product Cost & Prices'!B6) -> 164.41149 | F6: =((C6-D6) * 'Product Cost & Prices'!F6) -> 400 | G6: =((C6-D6) * 'Product Cost & Prices'!F6) - ((C6-D6) * 'Product Cost & Prices'!B6) -> 235.58851 | I6: 5 | J6: =I6 -> 5 | K6: 0 | L6: =(J6-K6) * 'Product Cost & Prices'!B6 -> 82.205745 | M6: =(J6-K6) * 'Product Cost & Prices'!E6 -> 175 | N6: =(J6-K6) * 'Product Cost & Prices'!E6 -> 175 | O6: =((J6-K6) * 'Product Cost & Prices'!E6) - ((J6-K6) * 'Product Cost & Prices'!B6) -> 92.794255 | Q6: =P6*'Genaral Bun Cost Calculator'!D14 -> 0 | T6: Vehicle Fuel & Maintainance | U6: 1000
A7: Jam Bun | B7: 50 | C7: 40 | D7: 8 | E7: =((C7-D7) * 'Product Cost & Prices'!B7) -> 640.59381 | F7: =((C7-D7) * 'Product Cost & Prices'!F7) -> 1600 | G7: =((C7-D7) * 'Product Cost & Prices'!F7) - ((C7-D7) * 'Product Cost & Prices'!B7) -> 959.40619 | I7: 16 | J7: =I7 -> 16 | K7: 0 | L7: =(J7-K7) * 'Product Cost & Prices'!B7 -> 320.2969 | M7: =(J7-K7) * 'Product Cost & Prices'!E7 -> 720 | N7: =(J7-K7) * 'Product Cost & Prices'!E7 -> 720 | O7: =((J7-K7) * 'Product Cost & Prices'!E7) - ((J7-K7) * 'Product Cost & Prices'!B7) -> 399.7031 | Q7: =P7*'Genaral Bun Cost Calculator'!D21 -> 0 | T7: Timber | U7: 1000
A8: Roast Bread | B8: 60 | C8: 60 | D8: 10 | E8: =((C8-D8) * 'Product Cost & Prices'!B14) -> 620.64607 | F8: =((C8-D8) * 'Product Cost & Prices'!F14) -> 1750 | G8: =((C8-D8) * 'Product Cost & Prices'!F14) - ((C8-D8) * 'Product Cost & Prices'!B14) -> 1129.3539 | I8: 29 | J8: =I8 -> 29 | K8: 0 | L8: =(J8-K8) * 'Product Cost & Prices'!B14 -> 359.97472 | M8: =(J8-K8) * 'Product Cost & Prices'!E14 -> 870 | N8: =(J8-K8) * 'Product Cost & Prices'!E14 -> 870 | O8: =((J8-K8) * 'Product Cost & Prices'!E14) - ((J8-K8) * 'Product Cost & Prices'!B14) -> 510.02528 | Q8: =P8*'Roast Bread Cost Calculator'!E9 -> 0 | T8: Father's Allocation | U8: 0
A9: Pizza | B9: 10 | C9: 10 | D9: 3 | E9: =((C9-D9) * 'Product Cost & Prices'!B8) -> 320.31807 | F9: =((C9-D9) * 'Product Cost & Prices'!F8) -> 700 | G9: =((C9-D9) * 'Product Cost & Prices'!F8) - ((C9-D9) * 'Product Cost & Prices'!B8) -> 379.68193 | I9: 0 | J9: 0 | K9: 0 | L9: =(J9-K9) * 'Product Cost & Prices'!B8 -> 0 | M9: =(J9-K9) * 'Product Cost & Prices'!E8 -> 0 | N9: =(J9-K9) * 'Product Cost & Prices'!E8 -> 0 | O9: =((J9-K9) * 'Product Cost & Prices'!E8) - ((J9-K9) * 'Product Cost & Prices'!B8) -> 0 | T9: Mother's Allocation | U9: 0
A10: Sausages Bun | C10: 0 | D10: 0 | E10: =((C10-D10) * 'Product Cost & Prices'!B9) -> 0 | F10: =((C10-D10) * 'Product Cost & Prices'!F9) -> 0 | G10: =((C10-D10) * 'Product Cost & Prices'!F9) - ((C10-D10) * 'Product Cost & Prices'!B9) -> 0 | I10: 0 | J10: =I10 -> 0 | K10: 0 | L10: =(J10-K10) * 'Product Cost & Prices'!B9 -> 0 | M10: =(J10-K10) * 'Product Cost & Prices'!E9 -> 0 | N10: 0 | O10: =((J10-K10) * 'Product Cost & Prices'!E9) - ((J10-K10) * 'Product Cost & Prices'!B9) -> 0 | T10: Salary Advance
A11: T-Bun | C11: 12 | D11: 12 | E11: =((C11-D11) * 'Product Cost & Prices'!B10) -> 0 | F11: =((C11-D11) * 'Product Cost & Prices'!F10) -> 0 | G11: =((C11-D11) * 'Product Cost & Prices'!F10) - ((C11-D11) * 'Product Cost & Prices'!B10) -> 0 | I11: 5 | J11: =I11 -> 5 | K11: 0 | L11: =(J11-K11) * 'Product Cost & Prices'!B10 -> 158.51087 | M11: =(J11-K11) * 'Product Cost & Prices'!E10 -> 225 | N11: =(J11-K11) * 'Product Cost & Prices'!E10 -> 225 | O11: =((J11-K11) * 'Product Cost & Prices'!E10) - ((J11-K11) * 'Product Cost & Prices'!B10) -> 66.48913 | T11: Not received
A12: Cream Bun (2 Pieces) | C12: 10 | D12: 6 | E12: =((C12-D12) * 'Product Cost & Prices'!B11) -> 144.73605 | F12: =((C12-D12) * 'Product Cost & Prices'!F11) -> 240 | G12: =((C12-D12) * 'Product Cost & Prices'!F11) - ((C12-D12) * 'Product Cost & Prices'!B11) -> 95.263949 | I12: 0 | J12: =I12 -> 0 | K12: 0 | L12: =(J12-K12) * 'Product Cost & Prices'!B11 -> 0 | M12: =(J12-K12) * 'Product Cost & Prices'!E11 -> 0 | N12: =(J12-K12) * 'Product Cost & Prices'!E11 -> 0 | O12: =((J12-K12) * 'Product Cost & Prices'!E11) - ((J12-K12) * 'Product Cost & Prices'!B11) -> 0 | T12: Total | U12: =SUM(U2:U11) -> 6000
A13: Wandu | B13: 20 | C13: 20 | D13: 0 | E13: =((C13-D13) * 'Product Cost & Prices'!B12) -> 475.72 | F13: =((C13-D13) * 'Product Cost & Prices'!F12) -> 1000 | G13: =((C13-D13) * 'Product Cost & Prices'!F12) - ((C13-D13) * 'Product Cost & Prices'!B12) -> 524.28 | I13: 6 | J13: =I13 -> 6 | K13: 0 | L13: =(J13-K13) * 'Product Cost & Prices'!B12 -> 142.716 | M13: =(J13-K13) * 'Product Cost & Prices'!E12 -> 270 | N13: =(J13-K13) * 'Product Cost & Prices'!E12 -> 270 | O13: =((J13-K13) * 'Product Cost & Prices'!E12) - ((J13-K13) * 'Product Cost & Prices'!B12) -> 127.284
A14: Cup Cake | C14: 0 | D14: 0 | E14: =((C14-D14) * 'Product Cost & Prices'!B15) -> 0 | F14: =((C14-D14) * 'Product Cost & Prices'!F15) -> 0 | I14: 0 | J14: =I14 -> 0 | K14: 0 | L14: =(J14-K14) * 'Product Cost & Prices'!B15 -> 0 | M14: =(J14-K14) * 'Product Cost & Prices'!E13 -> 0 | N14: =(J14-K14) * 'Product Cost & Prices'!E15 -> 0 | O14: =((J14-K14) * 'Product Cost & Prices'!E15) - ((J14-K14) * 'Product Cost & Prices'!B15) -> 0
A15: Wafers Cake | C15: 0 | D15: 0 | E15: =((C15-D15) * 'Product Cost & Prices'!B13) -> 0 | F15: =((C15-D15) * 'Product Cost & Prices'!F13) -> 0 | G15: =((C15-D15) * 'Product Cost & Prices'!F13) - ((C15-D15) * 'Product Cost & Prices'!B13) -> 0 | I15: 0 | J15: =I15 -> 0 | K15: 0 | L15: =(J15-K15) * 'Product Cost & Prices'!B13 -> 0 | M15: =(J15-K15) * 'Product Cost & Prices'!E13 -> 0 | N15: =(J15-K15) * 'Product Cost & Prices'!E13 -> 0 | O15: =((J15-K15) * 'Product Cost & Prices'!E13) - ((J15-K15) * 'Product Cost & Prices'!B13) -> 0
A16: pieces packet | C16: 0 | I16: 0 | N16: 0
A17: Butter Buscuit | C17: 0 | I17: 0
A18: Burger Bun | C18: 0 | D18: 0 | E18: =((C18-D18) * 'Product Cost & Prices'!B16) -> 0 | F18: =((C18-D18) * 'Product Cost & Prices'!F16) -> 0
A19: Bread (For Resale) | C19: 26 | E19: =((C19-D19) * 'Product Cost & Prices'!B4) -> 1963.1857 | F19: =((C19-D19) * 'Product Cost & Prices'!F4) -> 2860 | G19: =((C19-D19) * 'Product Cost & Prices'!F4) - ((C19-D19) * 'Product Cost & Prices'!B4) -> 896.81429
A20: Total Profit | E20: =SUM(E3:E19) -> 7816.6239 | F20: =SUM(F3:F19)+280 -> 15910 | G20: =SUM(G3:G19) -> 7813.3761 | I20: Total Profit | L20: =SUM(L3:L15) -> 2330.8436 | M20: =SUM(M3:M15) -> 4295 | N20: =SUM(N3:N16) -> 4295 | O20: =SUM(O3:O15) -> 1964.1564 | Q20: =sum(Q3:Q17) -> 0
A21: Gross Profit | F21: =sum(F20-E20) -> 8093.3761 | I21: Gross Profit | O21: =SUM(N20-L20) -> 1964.1564
C24: =CONCAT("Income for ", TEXT(Today(), "MMMM d, yyyy")) -> Income for January 11, 2026 | K24: =SUM(F20+N20) -> 20205
C25: =CONCAT("Cost for ", TEXT(Today(), "MMMM d, yyyy")) -> Cost for January 11, 2026 | K25: =SUM(E20+L20) + U12 -> 16147.468
C26: =CONCAT("Gross Profit for ", TEXT(Today(), "MMMM d, yyyy")) -> Gross Profit for January 11, 2026 | K26: =SUM(F21+O21) -> 10057.532
C27: =CONCAT("Net Profit for ", TEXT(Today(), "MMMM d, yyyy")) -> Net Profit for January 11, 2026 | K27: =SUM(K24-K25) -> 4057.5324
C39: Amount | D39: Note Count | E39: Total | P39: `
C40: 20 | E40: =C40*D40 -> 0
C41: 50 | D41: 6 | E41: =C41*D41 -> 300
C42: 100 | D42: 75 | E42: =C42*D42 -> 7500
C43: 500 | D43: 17 | E43: =C43*D43 -> 8500
C44: 1000 | D44: 10 | E44: =C44*D44 -> 10000
C45: 5000 | D45: 0 | E45: =C45*D45 -> 0
E46: =SUM(E40:E45) -> 26300

Sheet Ingredients Price
A1: Ingredient | B1: Unit | C1: Price per Unit (in local currency) | D1: Last Updated
A2: Flour | B2: kg | C2: =8800/50 -> 176
A3: Yeast | B3: kg | C3: 1900
A4: Sugar | B4: kg | C4: 208
A5: Salt | B5: kg | C5: 130
A6: Bread Improver (Hyco) | B6: kg | C6: 501
A7: Coconut Oil | B7: L | C7: =900 -> 900
A8: Jam | B8: kg | C8: 420
A9: Bun Compound (Masterbun) | B9: kg | C9: =8400/15 -> 560
A10: Onion | B10: kg | C10: 100
A11: Chilli Flakes | B11: kg | C11: 700
A12: Pepper | B12: kg | C12: 2650
A13: Leaks | B13: kg | C13: 0
A14: Eggs | B14: piece | C14: 31
A15: Sousages | B15: piece | C15: 0
A16: Tomato Sauce | B16: L | C16: 625
A17: Bun Yeast | B17: kg | C17: 1900
A18: Marvo | B18: kg | C18: 1200
A19: Icing Suger | B19: kg | C19: 450
A20: Cumin (දුරු ) | B20: kg | C20: 545
A21: Vanilla Flavour | B21: L | C21: 2840
... A23: Cake Magarine | B23: kg | C23: 900
A24: Wafers Piece | B24: piece | C24: =1900/420 -> 4.5238095
A25: Baking Power (N) | B25: kg | C25: 850
A26: Baking Power (Dual Action) | B26: kg | C26: 1715
A27: Ajinomoto | B27: kg | C27: 680
A28: Cup cake mixture | B28: Kg | C28: 760
A29: Vegetable Oil | B29: Kg | C29: 800
A30: Lettuce | B30: Kg | C30: 1000

Sheet CAKE COST CALCULATOR
A2: Ingredient | B2: Quantity | C2: Unit | D2: Price per Unit (in local currency) | E2: Cost for Recipe
A3: Flour | B3: 2 | C3: kg | D3: ='Ingredients Price'!C2 -> 176 | E3: =B3*D3 -> 352
A4: Sugar | B4: 2 | C4: kg | D4: ='Ingredients Price'!C4 -> 208 | E4: =B4*D4 -> 416
A5: Behaive | B5: 2 | C5: kg | D5: 1825 | E5: 1825
A6: Milk Powder | B6: 25 | C6: g | D6: 50 | E6: 50
A7: Corn Flour | B7: 200 | C7: g | D7: 120 | E7: 120
A8: Vanila | B8: 1 | C8: tsp | E8: 50
A9: Baking Powder | B9: 20 | C9: g | E9: 50
A10: Egg | B10: 30 | D10: 29 | E10: =D10*B10 -> 870
A11: Total Cost | E11: =SUM(E3:E10) -> 3733
A12: COST PER 1 KG | E12: =E11/7 -> 533.28571
C14: SELLING PRICE | E14: 890

Sheet Product Cost & Prices
A1: Product | B1: Cost | C1: Profit Margin (%) | D1: Profit Margin Price | E1: Shop Price | F1: Vehicle Price | H1: Shop Profit
A2: Bread | B2: ='Bread Cost Calculator'!E9 -> 75.507143 | C2: 39 | D2: =B2 * (1 + C2 / 100) -> 104.95493 | E2: =130-I2 -> 110 | F2: 130 | H2: Bread | I2: 20
A3: Sandwitch Bread | B3: ='Bread Cost Calculator'!E9 -> 75.507143 | C3: 39 | D3: =B3 * (1 + C3 / 100) -> 104.95493 | E3: =150-I3 -> 145 | F3: 150 | H3: Others | I3: 5
A4: Bread (For Resale) | B4: ='Bread Cost Calculator'!E9 -> 75.507143 | C4: 39 | D4: =B4 * (1 + C4 / 100) -> 104.95493 | E4: - | F4: 110
A5: Fish Bun | B5: ='Genaral Bun Cost Calculator'!D32 -> 19.21889 | C5: 80 | D5: =B5 * (1 + C5 / 100) -> 34.594002 | E5: =60-I3 -> 55 | F5: 60
A6: Wiyan Roll | B6: ='Genaral Bun Cost Calculator'!D14 -> 16.441149 | C6: 55 | D6: =B6 * (1 + C6 / 100) -> 25.483781 | E6: =40-I3 -> 35 | F6: 40
A7: Jam Bun | B7: ='Genaral Bun Cost Calculator'!D21 -> 20.018557 | C7: 60 | D7: =B7 * (1 + C7 / 100) -> 32.02969 | E7: =50-I3 -> 45 | F7: 50
A8: Pizza | B8: ='Genaral Bun Cost Calculator'!D40 -> 45.759725 | C8: 170 | D8: =B8 * (1 + C8 / 100) -> 123.55126 | E8: =100-I3 -> 95 | F8: 100
A9: Sausages Bun | B9: ='Genaral Bun Cost Calculator'!D47 -> 32.265373 | C9: 100 | D9: =B9 * (1 + C9 / 100) -> 64.530745 | E9: =80-I3 -> 75 | F9: 80
A10: T-Bun | B10: ='Bun Cost Calculator'!F19 -> 31.702174 | C10: 50 | D10: =B10 * (1 + C10 / 100) -> 47.553261 | E10: =50-I3 -> 45 | F10: 50
A11: Cream Bun (2 Pieces) | B11: ='Bun Cost Calculator'!D14 * 2 -> 36.184013 | C11: 50 | D11: =B11 * (1 + C11 / 100) -> 54.276019 | E11: =60-I3 -> 55 | F11: 60
A12: Wandu | B12: ='Wandu Cost Calculator'!D9 -> 23.786 | C12: 50 | D12: =B12 * (1 + C12 / 100) -> 35.679 | E12: =50-I3 -> 45 | F12: 50
A13: Wafers Cake | B13: ='Wafers Cake Cost Calculator'!D14 -> 26.70904 | C13: 50 | D13: =B13 * (1 + C13 / 100) -> 40.06356 | E13: =70-I3 -> 65 | F13: 70
A14: Roast Bread | B14: ='Roast Bread Cost Calculator'!E9 -> 12.412921 | C14: 80 | D14: =B14 * (1 + C14 / 100) -> 22.343258 | E14: =35-I3 -> 30 | F14: 35
A15: Cup Cake | B15: ='Cup Cake Cost Calculator'!D9 -> 33.885714 | C15: 100 | D15: =B15 * (1 + C15 / 100) -> 67.771429 | E15: =60-I3 -> 55 | F15: 60
A16: Burger Bun | B16: ='Genaral Bun Cost Calculator'!D55 -> 57.826391 | C16: 100 | D16: =B16 * (1 + C16 / 100) -> 115.65278 | E16: =90-I3 -> 85 | F16: 90

Sheet Bread Cost Calculator
A1: Ingredient | B1: Quantity | C1: Unit | D1: Price per Unit (in local currency) | E1: Cost for Recipe
A2: Flour | B2: 24 | C2: kg | D2: ='Ingredients Price'!C2 -> 176 | E2: =B2*'Ingredients Price'!C2 -> 4224
A3: Yeast | B3: 0.2 | C3: kg | D3: ='Ingredients Price'!C3 -> 1900 | E3: =B3*'Ingredients Price'!C3 -> 380
A4: Sugar | B4: 0.6 | C4: kg | D4: ='Ingredients Price'!C4 -> 208 | E4: =B4*'Ingredients Price'!C4 -> 124.8
A5: Salt | B5: 0.2 | C5: kg | D5: ='Ingredients Price'!C5 -> 130 | E5: =B5*'Ingredients Price'!C5 -> 26
A6: Bread Improver (Hyco) | B6: 0.7 | C6: kg | D6: ='Ingredients Price'!C6 -> 501 | E6: =B6*'Ingredients Price'!C6 -> 350.7
A7: Coconut Oil | B7: 0.2 | C7: L | D7: ='Ingredients Price'!C7 -> 900 | E7: =B7*'Ingredients Price'!C7 -> 180
A8: Total Cost | E8: =SUM(E2:E7) -> 5285.5
A9: Cost per Bread | E9: =E8/70 -> 75.507143

Sheet Roast Bread Cost Calculator
A1: Ingredient | B1: Quantity | C1: Unit | D1: Price per Unit (in local currency) | E1: Cost for Recipe
A2: Flour | B2: 8 | C2: kg | D2: ='Ingredients Price'!C2 -> 176 | E2: =B2*'Ingredients Price'!C2 -> 1408
A3: Yeast | B3: 0.04 | C3: kg | D3: ='Ingredients Price'!C3 -> 1900 | E3: =B3*'Ingredients Price'!C3 -> 76
A4: Sugar | B4: 0.7 | C4: kg | D4: ='Ingredients Price'!C4 -> 208 | E4: =B4*'Ingredients Price'!C4 -> 145.6
A5: Salt | B5: 0.15 | C5: kg | D5: ='Ingredients Price'!C5 -> 130 | E5: =B5*'Ingredients Price'!C5 -> 19.5
A6: Bread Improver (Hyco) | B6: 0.4 | C6: kg | D6: ='Ingredients Price'!C6 -> 501 | E6: =B6*'Ingredients Price'!C6 -> 200.4
A7: Coconut Oil | B7: 0.4 | C7: L | D7: ='Ingredients Price'!C7 -> 900 | E7: =B7*'Ingredients Price'!C7 -> 360
A8: Total Cost | E8: =SUM(E2:E7) -> 2209.5
A9: Cost per Bread | E9: =E8/178 -> 12.412921

Sheet Genaral Bun Cost Calculator
A1: Ingredient | B1: Quantity | C1: Unit | D1: Cost for Recipe
A2: Flour | B2: 10 | C2: kg | D2: =B2*'Ingredients Price'!C2 -> 1760
A3: Yeast | B3: 0.1 | C3: kg | D3: =B3*'Ingredients Price'!C3 -> 190
A4: Sugar | B4: 1 | C4: kg | D4: =B4*'Ingredients Price'!C4 -> 208
A5: Salt | B5: 0.1 | C5: kg | D5: =B5*'Ingredients Price'!C5 -> 13
A6: Bun Compound | B6: 0.5 | C6: kg | D6: =B6*'Ingredients Price'!C9 -> 280
A7: Coconut Oil | B7: 0.2 | C7: L | D7: =B7*'Ingredients Price'!C7 -> 180
A8: Total Cost | D8: =SUM(D2:D7) -> 2631
A10: Wiyan Roll
A11: Ingredient | B11: Quantity | C11: Unit | D11: Cost for Recipe
A12: Suger (Wrapping) | B12: 0.5 | C12: kg | D12: =B12*'Ingredients Price'!C4 -> 104
A13: Total Cost | D13: =SUM(F66,D12) -> 115.8088
A14: Cost per Item | D14: =SUM(F66) + SUM(D13)/B66 -> 16.441149
A16: Jam Banis
A17: Ingredient | B17: Quantity | C17: Unit | D17: Cost for Recipe
A18: Suger (Wrapping) | B18: 0.8 | C18: kg | D18: =B18*'Ingredients Price'!C4 -> 166.4
A19: Jam | B19: 0.3 | C19: kg | D19: =B19*'Ingredients Price'!C8 -> 126
A20: Total Cost | D20: =SUM(D18:D19) -> 292.4
A21: Cost per Item | D21: =SUM(F67) + SUM(D20)/B67 -> 20.018557
A23: Fish Bun
A24: Ingredient | B24: Quantity | C24: Unit | D24: Cost for Recipe
A25: Onion | B25: 2 | C25: kg | D25: =B25*'Ingredients Price'!C10 -> 200
A26: Salt | B26: 0.01 | C26: kg | D26: =B26*'Ingredients Price'!C5 -> 1.3
A27: Chilli Flakes | B27: 0.05 | C27: kg | D27: =B27*'Ingredients Price'!C11 -> 35
A28: Pepper | B28: 0.02 | C28: kg | D28: =B28*'Ingredients Price'!C12 -> 53
A29: Ajinomoto | B29: 0.02 | C29: kg | D29: =B29*'Ingredients Price'!C27 -> 13.6
A30: Coconut Oil | B30: 0.25 | C30: l | D30: =B30*'Ingredients Price'!C7 -> 225
A31: Total Cost | D31: =SUM(D25:D29) -> 302.9
A32: Cost per Item | D32: =SUM(F65) + SUM(D31)/B65 -> 19.21889
A34: Pizza
A35: Ingredient | B35: Quantity | C35: Unit | D35: Cost for Recipe
A36: Leaks | B36: 0.02 | C36: kg | D36: =B36*'Ingredients Price'!C13 -> 0
A37: Eggs | B37: 5 | C37: piece | D37: =B37*'Ingredients Price'!C14 -> 155
A38: Sousages | B38: 2 | C38: piece | D38: =B38*'Ingredients Price'!C15 -> 0
A39: Total Cost | D39: =SUM(D35:D37) -> 155
A40: Cost per Item | D40: =SUM(F68) + SUM(D39)/B68 -> 45.759725
A42: Sousages Bun
A43: Ingredient | B43: Quantity | C43: Unit | D43: Cost for Recipe
A44: Tomato Sauce | B44: 0.02 | C44: L | D44: =B44*'Ingredients Price'!C16 -> 12.5
A45: Sousages | B45: 8 | C45: piece | D45: =B45*'Ingredients Price'!C15 -> 0
...

Sheet Bun Cost Calculator
A1: Ingredient | B1: Quantity | C1: Unit | D1: Cost for Recipe
A2: Flour | B2: 3 | C2: kg | D2: =B2*'Ingredients Price'!C2 -> 528
A3: Bun Yeast | B3: 0.8 | C3: kg | D3: =B3*'Ingredients Price'!C17 -> 1520
A4: Sugar | B4: 1 | C4: kg | D4: =B4*'Ingredients Price'!C4 -> 208
A5: Salt | B5: 0.05 | C5: kg | D5: =B5*'Ingredients Price'!C5 -> 6.5
A6: Bun Compound | B6: 0.3 | C6: kg | D6: =B6*'Ingredients Price'!C9 -> 168
A7: Eggs | B7: 2 | C7: piece | D7: =B7*'Ingredients Price'!C14 -> 62
A8: Total Cost | B8: ` | D8: =SUM(D2:D6) -> 2430.5
A10: Cream Bun | E10: Cream Cost
A11: Ingredient | B11: Quantity | C11: Unit | D11: Cost for Recipe | E11: Ingredient | F11: Quantity | G11: Unit | H11: Cost for Recipe
A12: Cream | B12: 0.01 | C12: kg | D12: =B12*H14 -> 23.025 | E12: Marvo | F12: 1 | G12: kg | H12: =F12*'Ingredients Price'!C18 -> 1200
A13: Total Cost | D13: =SUM(D12) -> 23.025 | E13: Icing Suger | F13: 2.45 | G13: kg | H13: =F13*'Ingredients Price'!C19 -> 1102.5
A14: Cost per Item | D14: =SUM(F20) + SUM(D13)/B20 -> 18.092006 | E14: Total | H14: =SUM(H11:H13) -> 2302.5
A18: Product | B18: Output (pieces) | C18: Dough Weight (KG) | D18: Total Weight (KG) | E18: Cost Contribution | F18: Cost Per Bun
A19: T Bun | B19: 50 | C19: 0.09 | D19: =B19*C19 -> 4.5 | E19: =(D8/D21)*D19 -> 1585.1087 | F19: =SUM(E19/B19) -> 31.702174
A20: Cream Bun | B20: 48 | C20: 0.05 | D20: =B20*C20 -> 2.4 | E20: =(D8/D21)*D20 -> 845.3913 | F20: =SUM(E20/B20) -> 17.612319
D21: =SUM(D19:D20) -> 6.9

Sheet Wandu Cost Calculator
A1: Ingredient | B1: Quantity | C1: Unit | D1: Cost for Recipe
A2: Flour | B2: 2 | C2: kg | D2: =B2*'Ingredients Price'!C2 -> 352
A3: Baking Power (N) | B3: 0.05 | C3: kg | D3: =B3*'Ingredients Price'!C25 -> 42.5
A4: Sugar | B4: 0.8 | C4: kg | D4: =B4*'Ingredients Price'!C4 -> 166.4
A5: Cumins | B5: 0.05 | C5: kg | D5: =B5*'Ingredients Price'!C20 -> 27.25
A6: Salt | B6: 0.05 | C6: kg | D6: =B6*'Ingredients Price'!C5 -> 6.5
A7: Total Cost | B7: ` | D7: =SUM(D2:D6) -> 594.65
A9: Cost Per Wandu | D9: =D7/25 -> 23.786

Sheet Wafers Cake Cost Calculator
A1: Ingredient | B1: Quantity | C1: Unit | D1: Cost for Recipe
A2: Flour | B2: 1 | C2: kg | D2: =B2*'Ingredients Price'!C2 -> 176
A3: Cake Magarine | B3: 1 | C3: kg | D3: =B3*'Ingredients Price'!C9 -> 560
A4: Sugar | B4: 1 | C4: kg | D4: =B4*'Ingredients Price'!C4 -> 208
A5: Eggs | B5: 15 | C5: pieces | D5: =B5*'Ingredients Price'!C14 -> 465
A6: Vanilla Flavour | B6: 0.01 | C6: L | D6: =B6*'Ingredients Price'!C21 -> 28.4
A7: Food Coloring | B7: 0.01 | C7: L | D7: =B7*'Ingredients Price'!C22 -> 57.14
A8: Wafers Piece | B8: 2 | C8: pieces | D8: =B8*'Ingredients Price'!C24 -> 9.047619
A9: Icing | B9: 0.25 | C9: Kg | D9: =B9*'Ingredients Price'!C19 -> 112.5
A10: Marvo | B10: 0.1 | C10: kg | D10: =B10*'Ingredients Price'!C18 -> 120
A11: Total Cost | B11: ` | D11: =SUM(D2:D10) -> 1736.0876
A14: Cost Per Cake Piece | D14: =D11/65 -> 26.70904

Sheet Cup Cake Cost Calculator
A1: WITH CUP CAKE MIXTURE
A2: Ingredient | B2: Quantity | C2: Unit | D2: Cost for Recipe
A3: Mixture | B3: 1 | C3: kg | D3: =B3*'Ingredients Price'!C28 -> 760
A4: Eggs | B4: 6 | C4: pieces | D4: =B4*'Ingredients Price'!C14 -> 186
A5: Vegetable Oil | B5: 0.3 | C5: kg | D5: =B5*'Ingredients Price'!C29 -> 240
A6: Total Cost | B6: ` | D6: =SUM(D3:D5) -> 1186
A9: Cost Per Cake Piece | D9: =D6/35 -> 33.885714
A12: WITH CAKE MAGARINE
A13: Ingredient | B13: Quantity | C13: Unit | D13: Cost for Recipe
A14: Flour | B14: 1 | C14: kg | D14: =B14*'Ingredients Price'!C2 -> 176
A15: Cake Magarine | B15: 1 | C15: kg | D15: =B15*'Ingredients Price'!C23 -> 900
A16: Sugar | B16: 1 | C16: kg | D16: =B16*'Ingredients Price'!C4 -> 208
A17: Eggs | B17: 15 | C17: pieces | D17: =B17*'Ingredients Price'!C14 -> 465
A18: Vanilla Flavour | B18: 0.01 | C18: L | D18: =B18*'Ingredients Price'!C21 -> 28.4
A19: Baking Powder | B19: 0.02 | C19: Kg | D19: =B19*'Ingredients Price'!C25 -> 17
A20: Total Cost | B20: ` | D20: =SUM(D14:D19) -> 1794.4
A22: Cost Per Cake Piece | D22: =D20/70 -> 25.634286
